Workbook
Name \a: #REF!
Name \C: #REF!
Name \W: #REF!
Name \X: #REF!
Name \Y: #REF!
Name _: #REF!
Name _.Next: #REF!
Name _?: #N/A
Name _?쨲?f: #REF!
Name ______R3_t: #N/A
Name __01: #REF!
Name __02: #REF!
Name __GoA1: __GoA1
Name _￡A￡´1: #N/A
Name _￡A￡´2: #N/A
Name _01: #REF!
Name _02: #REF!
Name _1: #REF!
Name _1.1_Heat_radiation: #REF!
Name _1.10_Operation_stroke: #REF!
Name _1.11_Holding_force_of_door: #REF!
Name _1.12_Water_flow_noise: #REF!
Name _1.13_Smell: #REF!
Name _1.2_Air_flow_resistance: #REF!
Name _1.3_Air_flow_distribution: #REF!
Name _1.4_Temp._control: #REF!
Name _1.5_Warm_water_pressure: #REF!
Name _1.6_Air_leak: #REF!
Name _1.7_Operating_force: #REF!
Name _1.8_Operating_feel: #REF!
Name _1.9_Operation_noise: #REF!
Name _1_01: #REF!
Name _1_C17_S61: [1]dfmea!#REF!
Name _10_?__POINT: #REF!
Name _10_?쨲?f: #REF!
Name _102M123_: [2]!_102M123_
Name _103M123_: [2]!_103M123_
Name _104M123_: [2]!_104M123_
Name _106M678_: [2]!_106M678_
Name _110M678_: [2]!_110M678_
Name _111M678_: [2]!_111M678_
Name _112M678_: [2]!_112M678_
Name _114M6789_: [2]!_114M6789_
Name _118M6789_: [2]!_118M6789_
Name _119M6789_: [2]!_119M6789_
Name _12._FAN_MOTOR_부품_비교표: #REF!
Name _120AA1_: #REF!
Name _120M6789_: [2]!_120M6789_
Name _121n_0Extr: #REF!
Name _122n__Extr: #REF!
Name _124Q123_: [2]!_124Q123_
Name _128Q123_: [2]!_128Q123_
Name _129Q123_: [2]!_129Q123_
Name _130Q123_: [2]!_130Q123_
Name _132x1_: #REF!
Name _134x2_: #REF!
Name _147ÁÖ¿ä¹_Á_Á¡: #REF!
Name _15¿¹_êÃÑ°ý½ÃÆ_¼³ONLY: #REF!
Name _16_?쨲?f: #REF!
Name _170AO¿a¹RA_A¡: #REF!

Sheet DFMEA标准表格
D1: 设计失效模式及后果分析（DFMEA） （标准表格）
D2: 系统分析 步骤1 - 策划与准备
D3: 公司名称： | H3: 项目名称： | P3: DFMEA ID编号：
D4: 工厂地址： | H4: DFMEA开始时间： | P4: 设计责任人：
D5: 顾客名称： | H5: DFMEA修订时间： | P5: 保密等级：
D6: 年型/项目： | H6: 跨职能小组：
C9: 持续改善 | D9: 系统分析 | J9: 失效分析及降低风险
D10: 步骤2 - structural analysis （结构分析） | G10: 步骤3 - Functional analysis （功能分析） | J10: 步骤4 - Failure analysis （失效分析） | N10: 步骤5 - Riske analysis （风险分析） | S10: 步骤6 - Optimization （优化）
B11: 问题# | C11: 历史/变更授权 (适用时} | D11: 1.上一高层级 | E11: 2.关注要素 | F11: 3.下一低层级或特性类型 | G11: 1.上一高层级功能及要求 | H11: 关注要素功能及要求 | I11: 下一低层级的功能及要求或特性 | J11: 1.对于上一高层级要素或最终用户的失效影响(FE) | K11: S | L11: 关注要素的失效模式(FM) | M11: 下一低层级要素或特性的失效原因(FC) | N11: 当前对失效起因的预防控制（PC) | O11: O | P11: 对失效起因或失效模式的当前探测控制（DC) | Q11: D | R11: AP | S11: 预防措施 | T11: 探测措施 | U11: 责任人姓名 | V11: 目标 完成日期 | W11: 状态 | X11: 措施证据 | Y11: 完成日期 | Z11: S | AA11: O | AB11: D | AC11: AP
R12: =IF(OR(K12="",O12="",Q12=""),"-",LOOKUP(1,0/((K12>=--MID([24]AP准则!$A$2:$A$70,1,FIND("-",[24]AP准则!$A$2:$A$70)-1))*(K12<=--MID([24]AP准则!$A$2:$A$70,FIND("-",[24]AP准则!$A$2:$A$70)+1,2))*(O12>=--MID([24]AP准则!$B$2:$B$70,1,FIND("-",[24]AP准则!$B$2:$B$70)-1))*(O12<=--MID([24]AP准则!$B$2:$B$70,FIND("-",[24]AP准则!$B$2:$B$70)+1,2))*(Q12>=--MID([24]AP准则!$C$2:$C$70,1,FIND("-",[24]AP准则!$C$2:$C$70)-1))*(Q12<=--MID([24]AP准则!$C$2:$C$70,FIND("-",[24]AP准则!$C$2:$C$70)+1,2))),[24]AP准则!$D$2:$D$70)) -> - | AC12: =IF(OR(Z12="",AA12="",AB12=""),"-",LOOKUP(1,0/((Z12>=--MID([24]AP准则!$A$2:$A$70,1,FIND("-",[24]AP准则!$A$2:$A$70)-1))*(Z12<=--MID([24]AP准则!$A$2:$A$70,FIND("-",[24]AP准则!$A$2:$A$70)+1,2))*(AA12>=--MID([24]AP准则!$B$2:$B$70,1,FIND("-",[24]AP准则!$B$2:$B$70)-1))*(AA12<=--MID([24]AP准则!$B$2:$B$70,FIND("-",[24]AP准则!$B$2:$B$70)+1,2))*(AB12>=--MID([24]AP准则!$C$2:$C$70,1,FIND("-",[24]AP准则!$C$2:$C$70)-1))*(AB12<=--MID([24]AP准则!$C$2:$C$70,FIND("-",[24]AP准则!$C$2:$C$70)+1,2))),[24]AP准则!$D$2:$D$70)) -> -
R13: =IF(OR(K13="",O13="",Q13=""),"-",LOOKUP(1,0/((K13>=--MID([24]AP准则!$A$2:$A$70,1,FIND("-",[24]AP准则!$A$2:$A$70)-1))*(K13<=--MID([24]AP准则!$A$2:$A$70,FIND("-",[24]AP准则!$A$2:$A$70)+1,2))*(O13>=--MID([24]AP准则!$B$2:$B$70,1,FIND("-",[24]AP准则!$B$2:$B$70)-1))*(O13<=--MID([24]AP准则!$B$2:$B$70,FIND("-",[24]AP准则!$B$2:$B$70)+1,2))*(Q13>=--MID([24]AP准则!$C$2:$C$70,1,FIND("-",[24]AP准则!$C$2:$C$70)-1))*(Q13<=--MID([24]AP准则!$C$2:$C$70,FIND("-",[24]AP准则!$C$2:$C$70)+1,2))),[24]AP准则!$D$2:$D$70)) -> -
R14: =IF(OR(K14="",O14="",Q14=""),"-",LOOKUP(1,0/((K14>=--MID([24]AP准则!$A$2:$A$70,1,FIND("-",[24]AP准则!$A$2:$A$70)-1))*(K14<=--MID([24]AP准则!$A$2:$A$70,FIND("-",[24]AP准则!$A$2:$A$70)+1,2))*(O14>=--MID([24]AP准则!$B$2:$B$70,1,FIND("-",[24]AP准则!$B$2:$B$70)-1))*(O14<=--MID([24]AP准则!$B$2:$B$70,FIND("-",[24]AP准则!$B$2:$B$70)+1,2))*(Q14>=--MID([24]AP准则!$C$2:$C$70,1,FIND("-",[24]AP准则!$C$2:$C$70)-1))*(Q14<=--MID([24]AP准则!$C$2:$C$70,FIND("-",[24]AP准则!$C$2:$C$70)+1,2))),[24]AP准则!$D$2:$D$70)) -> -
R15: =IF(OR(K15="",O15="",Q15=""),"-",LOOKUP(1,0/((K15>=--MID([24]AP准则!$A$2:$A$70,1,FIND("-",[24]AP准则!$A$2:$A$70)-1))*(K15<=--MID([24]AP准则!$A$2:$A$70,FIND("-",[24]AP准则!$A$2:$A$70)+1,2))*(O15>=--MID([24]AP准则!$B$2:$B$70,1,FIND("-",[24]AP准则!$B$2:$B$70)-1))*(O15<=--MID([24]AP准则!$B$2:$B$70,FIND("-",[24]AP准则!$B$2:$B$70)+1,2))*(Q15>=--MID([24]AP准则!$C$2:$C$70,1,FIND("-",[24]AP准则!$C$2:$C$70)-1))*(Q15<=--MID([24]AP准则!$C$2:$C$70,FIND("-",[24]AP准则!$C$2:$C$70)+1,2))),[24]AP准则!$D$2:$D$70)) -> -
R16: =IF(OR(K16="",O16="",Q16=""),"-",LOOKUP(1,0/((K16>=--MID([24]AP准则!$A$2:$A$70,1,FIND("-",[24]AP准则!$A$2:$A$70)-1))*(K16<=--MID([24]AP准则!$A$2:$A$70,FIND("-",[24]AP准则!$A$2:$A$70)+1,2))*(O16>=--MID([24]AP准则!$B$2:$B$70,1,FIND("-",[24]AP准则!$B$2:$B$70)-1))*(O16<=--MID([24]AP准则!$B$2:$B$70,FIND("-",[24]AP准则!$B$2:$B$70)+1,2))*(Q16>=--MID([24]AP准则!$C$2:$C$70,1,FIND("-",[24]AP准则!$C$2:$C$70)-1))*(Q16<=--MID([24]AP准则!$C$2:$C$70,FIND("-",[24]AP准则!$C$2:$C$70)+1,2))),[24]AP准则!$D$2:$D$70)) -> - | AC16: =IF(OR(Z16="",AA16="",AB16=""),"-",LOOKUP(1,0/((Z16>=--MID([24]AP准则!$A$2:$A$70,1,FIND("-",[24]AP准则!$A$2:$A$70)-1))*(Z16<=--MID([24]AP准则!$A$2:$A$70,FIND("-",[24]AP准则!$A$2:$A$70)+1,2))*(AA16>=--MID([24]AP准则!$B$2:$B$70,1,FIND("-",[24]AP准则!$B$2:$B$70)-1))*(AA16<=--MID([24]AP准则!$B$2:$B$70,FIND("-",[24]AP准则!$B$2:$B$70)+1,2))*(AB16>=--MID([24]AP准则!$C$2:$C$70,1,FIND("-",[24]AP准则!$C$2:$C$70)-1))*(AB16<=--MID([24]AP准则!$C$2:$C$70,FIND("-",[24]AP准则!$C$2:$C$70)+1,2))),[24]AP准则!$D$2:$D$70)) -> -
R17: =IF(OR(K17="",O17="",Q17=""),"-",LOOKUP(1,0/((K17>=--MID([24]AP准则!$A$2:$A$70,1,FIND("-",[24]AP准则!$A$2:$A$70)-1))*(K17<=--MID([24]AP准则!$A$2:$A$70,FIND("-",[24]AP准则!$A$2:$A$70)+1,2))*(O17>=--MID([24]AP准则!$B$2:$B$70,1,FIND("-",[24]AP准则!$B$2:$B$70)-1))*(O17<=--MID([24]AP准则!$B$2:$B$70,FIND("-",[24]AP准则!$B$2:$B$70)+1,2))*(Q17>=--MID([24]AP准则!$C$2:$C$70,1,FIND("-",[24]AP准则!$C$2:$C$70)-1))*(Q17<=--MID([24]AP准则!$C$2:$C$70,FIND("-",[24]AP准则!$C$2:$C$70)+1,2))),[24]AP准则!$D$2:$D$70)) -> - | AC17: =IF(OR(Z17="",AA17="",AB17=""),"-",LOOKUP(1,0/((Z17>=--MID([24]AP准则!$A$2:$A$70,1,FIND("-",[24]AP准则!$A$2:$A$70)-1))*(Z17<=--MID([24]AP准则!$A$2:$A$70,FIND("-",[24]AP准则!$A$2:$A$70)+1,2))*(AA17>=--MID([24]AP准则!$B$2:$B$70,1,FIND("-",[24]AP准则!$B$2:$B$70)-1))*(AA17<=--MID([24]AP准则!$B$2:$B$70,FIND("-",[24]AP准则!$B$2:$B$70)+1,2))*(AB17>=--MID([24]AP准则!$C$2:$C$70,1,FIND("-",[24]AP准则!$C$2:$C$70)-1))*(AB17<=--MID([24]AP准则!$C$2:$C$70,FIND("-",[24]AP准则!$C$2:$C$70)+1,2))),[24]AP准则!$D$2:$D$70)) -> -
R18: =IF(OR(K18="",O18="",Q18=""),"-",LOOKUP(1,0/((K18>=--MID([24]AP准则!$A$2:$A$70,1,FIND("-",[24]AP准则!$A$2:$A$70)-1))*(K18<=--MID([24]AP准则!$A$2:$A$70,FIND("-",[24]AP准则!$A$2:$A$70)+1,2))*(O18>=--MID([24]AP准则!$B$2:$B$70,1,FIND("-",[24]AP准则!$B$2:$B$70)-1))*(O18<=--MID([24]AP准则!$B$2:$B$70,FIND("-",[24]AP准则!$B$2:$B$70)+1,2))*(Q18>=--MID([24]AP准则!$C$2:$C$70,1,FIND("-",[24]AP准则!$C$2:$C$70)-1))*(Q18<=--MID([24]AP准则!$C$2:$C$70,FIND("-",[24]AP准则!$C$2:$C$70)+1,2))),[24]AP准则!$D$2:$D$70)) -> - | AC18: =IF(OR(Z18="",AA18="",AB18=""),"-",LOOKUP(1,0/((Z18>=--MID([24]AP准则!$A$2:$A$70,1,FIND("-",[24]AP准则!$A$2:$A$70)-1))*(Z18<=--MID([24]AP准则!$A$2:$A$70,FIND("-",[24]AP准则!$A$2:$A$70)+1,2))*(AA18>=--MID([24]AP准则!$B$2:$B$70,1,FIND("-",[24]AP准则!$B$2:$B$70)-1))*(AA18<=--MID([24]AP准则!$B$2:$B$70,FIND("-",[24]AP准则!$B$2:$B$70)+1,2))*(AB18>=--MID([24]AP准则!$C$2:$C$70,1,FIND("-",[24]AP准则!$C$2:$C$70)-1))*(AB18<=--MID([24]AP准则!$C$2:$C$70,FIND("-",[24]AP准则!$C$2:$C$70)+1,2))),[24]AP准则!$D$2:$D$70)) -> -

Sheet PFMEA标准表格
D1: 过程失效模式及后果分析（PFMEA） （标准表格）
D2: 系统分析 步骤1 - 策划与准备
D3: 公司名称： | H3: 项目名称： | P3: PFMEA ID编号：
D4: 工厂地址： | H4: PFMEA开始时间： | P4: 过程职责：
D5: 顾客名称： | H5: PFMEA修订时间： | P5: 保密等级：
D6: 年型/项目： | H6: 跨职能小组：
C9: 持续改善 | D9: 系统分析 | J9: 失效分析及降低风险
D10: 步骤2 - structural analysis （结构分析） | G10: 步骤3 - Functional analysis （功能分析） | J10: 步骤4 - Failure analysis （失效分析） | N10: 步骤5 - Riske analysis （风险分析） | V10: 步骤6 - Optimization （优化）
B11: 问题# | C11: 历史/变更授权 (适用时} | D11: 1.过程项 | E11: 2.过程步骤 | F11: 3.过程工作要素 | G11: 1.过程项目的功能 | H11: 2.过程步骤的功能和产品特性 （量值为可选项） | I11: 3.过程工作要素的功能和过程特性 | J11: 1.对于上一较高级别要素和\或最终用户的失效影响( FE ) | K11: S | L11: 2.过程步骤的失效模式（FM） | M11: 3.工作要素的失效起因（FC) | N11: 当前对失效起因的预防控制（PC) | O11: O | P11: 对失效起因或失效模式的当前探测控制（DC) | Q11: D | R11: AP | S11: 特殊特性 | T11: 筛选符号 | U11: （可选） | V11: 预防措施 | W11: 探测措施 | X11: 责任人姓名 | Y11: 目标 完成日期 | Z11: 状态 | AA11: 措施证据 | AB11: 完成日期 | AC11: S | AD11: O | AE11: D | AF11: AP | AG11: 特殊特性
R12: =IF(OR(K12="",O12="",Q12=""),"-",LOOKUP(1,0/((K12>=--MID([24]AP准则!$A$2:$A$70,1,FIND("-",[24]AP准则!$A$2:$A$70)-1))*(K12<=--MID([24]AP准则!$A$2:$A$70,FIND("-",[24]AP准则!$A$2:$A$70)+1,2))*(O12>=--MID([24]AP准则!$B$2:$B$70,1,FIND("-",[24]AP准则!$B$2:$B$70)-1))*(O12<=--MID([24]AP准则!$B$2:$B$70,FIND("-",[24]AP准则!$B$2:$B$70)+1,2))*(Q12>=--MID([24]AP准则!$C$2:$C$70,1,FIND("-",[24]AP准则!$C$2:$C$70)-1))*(Q12<=--MID([24]AP准则!$C$2:$C$70,FIND("-",[24]AP准则!$C$2:$C$70)+1,2))),[24]AP准则!$D$2:$D$70)) -> - | AC12: 8 | AD12: 3 | AE12: 2 | AF12: =IF(OR(AC12="",AD12="",AE12=""),"-",LOOKUP(1,0/((AC12>=--MID([24]AP准则!$A$2:$A$70,1,FIND("-",[24]AP准则!$A$2:$A$70)-1))*(AC12<=--MID([24]AP准则!$A$2:$A$70,FIND("-",[24]AP准则!$A$2:$A$70)+1,2))*(AD12>=--MID([24]AP准则!$B$2:$B$70,1,FIND("-",[24]AP准则!$B$2:$B$70)-1))*(AD12<=--MID([24]AP准则!$B$2:$B$70,FIND("-",[24]AP准则!$B$2:$B$70)+1,2))*(AE12>=--MID([24]AP准则!$C$2:$C$70,1,FIND("-",[24]AP准则!$C$2:$C$70)-1))*(AE12<=--MID([24]AP准则!$C$2:$C$70,FIND("-",[24]AP准则!$C$2:$C$70)+1,2))),[24]AP准则!$D$2:$D$70)) -> L
R13: =IF(OR(K13="",O13="",Q13=""),"-",LOOKUP(1,0/((K13>=--MID([24]AP准则!$A$2:$A$70,1,FIND("-",[24]AP准则!$A$2:$A$70)-1))*(K13<=--MID([24]AP准则!$A$2:$A$70,FIND("-",[24]AP准则!$A$2:$A$70)+1,2))*(O13>=--MID([24]AP准则!$B$2:$B$70,1,FIND("-",[24]AP准则!$B$2:$B$70)-1))*(O13<=--MID([24]AP准则!$B$2:$B$70,FIND("-",[24]AP准则!$B$2:$B$70)+1,2))*(Q13>=--MID([24]AP准则!$C$2:$C$70,1,FIND("-",[24]AP准则!$C$2:$C$70)-1))*(Q13<=--MID([24]AP准则!$C$2:$C$70,FIND("-",[24]AP准则!$C$2:$C$70)+1,2))),[24]AP准则!$D$2:$D$70)) -> -
R14: =IF(OR(K14="",O14="",Q14=""),"-",LOOKUP(1,0/((K14>=--MID([24]AP准则!$A$2:$A$70,1,FIND("-",[24]AP准则!$A$2:$A$70)-1))*(K14<=--MID([24]AP准则!$A$2:$A$70,FIND("-",[24]AP准则!$A$2:$A$70)+1,2))*(O14>=--MID([24]AP准则!$B$2:$B$70,1,FIND("-",[24]AP准则!$B$2:$B$70)-1))*(O14<=--MID([24]AP准则!$B$2:$B$70,FIND("-",[24]AP准则!$B$2:$B$70)+1,2))*(Q14>=--MID([24]AP准则!$C$2:$C$70,1,FIND("-",[24]AP准则!$C$2:$C$70)-1))*(Q14<=--MID([24]AP准则!$C$2:$C$70,FIND("-",[24]AP准则!$C$2:$C$70)+1,2))),[24]AP准则!$D$2:$D$70)) -> -
R15: =IF(OR(K15="",O15="",Q15=""),"-",LOOKUP(1,0/((K15>=--MID([24]AP准则!$A$2:$A$70,1,FIND("-",[24]AP准则!$A$2:$A$70)-1))*(K15<=--MID([24]AP准则!$A$2:$A$70,FIND("-",[24]AP准则!$A$2:$A$70)+1,2))*(O15>=--MID([24]AP准则!$B$2:$B$70,1,FIND("-",[24]AP准则!$B$2:$B$70)-1))*(O15<=--MID([24]AP准则!$B$2:$B$70,FIND("-",[24]AP准则!$B$2:$B$70)+1,2))*(Q15>=--MID([24]AP准则!$C$2:$C$70,1,FIND("-",[24]AP准则!$C$2:$C$70)-1))*(Q15<=--MID([24]AP准则!$C$2:$C$70,FIND("-",[24]AP准则!$C$2:$C$70)+1,2))),[24]AP准则!$D$2:$D$70)) -> -
R16: =IF(OR(K16="",O16="",Q16=""),"-",LOOKUP(1,0/((K16>=--MID([24]AP准则!$A$2:$A$70,1,FIND("-",[24]AP准则!$A$2:$A$70)-1))*(K16<=--MID([24]AP准则!$A$2:$A$70,FIND("-",[24]AP准则!$A$2:$A$70)+1,2))*(O16>=--MID([24]AP准则!$B$2:$B$70,1,FIND("-",[24]AP准则!$B$2:$B$70)-1))*(O16<=--MID([24]AP准则!$B$2:$B$70,FIND("-",[24]AP准则!$B$2:$B$70)+1,2))*(Q16>=--MID([24]AP准则!$C$2:$C$70,1,FIND("-",[24]AP准则!$C$2:$C$70)-1))*(Q16<=--MID([24]AP准则!$C$2:$C$70,FIND("-",[24]AP准则!$C$2:$C$70)+1,2))),[24]AP准则!$D$2:$D$70)) -> - | AF16: =IF(OR(AC16="",AD16="",AE16=""),"-",LOOKUP(1,0/((AC16>=--MID([24]AP准则!$A$2:$A$70,1,FIND("-",[24]AP准则!$A$2:$A$70)-1))*(AC16<=--MID([24]AP准则!$A$2:$A$70,FIND("-",[24]AP准则!$A$2:$A$70)+1,2))*(AD16>=--MID([24]AP准则!$B$2:$B$70,1,FIND("-",[24]AP准则!$B$2:$B$70)-1))*(AD16<=--MID([24]AP准则!$B$2:$B$70,FIND("-",[24]AP准则!$B$2:$B$70)+1,2))*(AE16>=--MID([24]AP准则!$C$2:$C$70,1,FIND("-",[24]AP准则!$C$2:$C$70)-1))*(AE16<=--MID([24]AP准则!$C$2:$C$70,FIND("-",[24]AP准则!$C$2:$C$70)+1,2))),[24]AP准则!$D$2:$D$70)) -> -
R17: =IF(OR(K17="",O17="",Q17=""),"-",LOOKUP(1,0/((K17>=--MID([24]AP准则!$A$2:$A$70,1,FIND("-",[24]AP准则!$A$2:$A$70)-1))*(K17<=--MID([24]AP准则!$A$2:$A$70,FIND("-",[24]AP准则!$A$2:$A$70)+1,2))*(O17>=--MID([24]AP准则!$B$2:$B$70,1,FIND("-",[24]AP准则!$B$2:$B$70)-1))*(O17<=--MID([24]AP准则!$B$2:$B$70,FIND("-",[24]AP准则!$B$2:$B$70)+1,2))*(Q17>=--MID([24]AP准则!$C$2:$C$70,1,FIND("-",[24]AP准则!$C$2:$C$70)-1))*(Q17<=--MID([24]AP准则!$C$2:$C$70,FIND("-",[24]AP准则!$C$2:$C$70)+1,2))),[24]AP准则!$D$2:$D$70)) -> - | AF17: =IF(OR(AC17="",AD17="",AE17=""),"-",LOOKUP(1,0/((AC17>=--MID([24]AP准则!$A$2:$A$70,1,FIND("-",[24]AP准则!$A$2:$A$70)-1))*(AC17<=--MID([24]AP准则!$A$2:$A$70,FIND("-",[24]AP准则!$A$2:$A$70)+1,2))*(AD17>=--MID([24]AP准则!$B$2:$B$70,1,FIND("-",[24]AP准则!$B$2:$B$70)-1))*(AD17<=--MID([24]AP准则!$B$2:$B$70,FIND("-",[24]AP准则!$B$2:$B$70)+1,2))*(AE17>=--MID([24]AP准则!$C$2:$C$70,1,FIND("-",[24]AP准则!$C$2:$C$70)-1))*(AE17<=--MID([24]AP准则!$C$2:$C$70,FIND("-",[24]AP准则!$C$2:$C$70)+1,2))),[24]AP准则!$D$2:$D$70)) -> -
R18: =IF(OR(K18="",O18="",Q18=""),"-",LOOKUP(1,0/((K18>=--MID([24]AP准则!$A$2:$A$70,1,FIND("-",[24]AP准则!$A$2:$A$70)-1))*(K18<=--MID([24]AP准则!$A$2:$A$70,FIND("-",[24]AP准则!$A$2:$A$70)+1,2))*(O18>=--MID([24]AP准则!$B$2:$B$70,1,FIND("-",[24]AP准则!$B$2:$B$70)-1))*(O18<=--MID([24]AP准则!$B$2:$B$70,FIND("-",[24]AP准则!$B$2:$B$70)+1,2))*(Q18>=--MID([24]AP准则!$C$2:$C$70,1,FIND("-",[24]AP准则!$C$2:$C$70)-1))*(Q18<=--MID([24]AP准则!$C$2:$C$70,FIND("-",[24]AP准则!$C$2:$C$70)+1,2))),[24]AP准则!$D$2:$D$70)) -> - | AF18: =IF(OR(AC18="",AD18="",AE18=""),"-",LOOKUP(1,0/((AC18>=--MID([24]AP准则!$A$2:$A$70,1,FIND("-",[24]AP准则!$A$2:$A$70)-1))*(AC18<=--MID([24]AP准则!$A$2:$A$70,FIND("-",[24]AP准则!$A$2:$A$70)+1,2))*(AD18>=--MID([24]AP准则!$B$2:$B$70,1,FIND("-",[24]AP准则!$B$2:$B$70)-1))*(AD18<=--MID([24]AP准则!$B$2:$B$70,FIND("-",[24]AP准则!$B$2:$B$70)+1,2))*(AE18>=--MID([24]AP准则!$C$2:$C$70,1,FIND("-",[24]AP准则!$C$2:$C$70)-1))*(AE18<=--MID([24]AP准则!$C$2:$C$70,FIND("-",[24]AP准则!$C$2:$C$70)+1,2))),[24]AP准则!$D$2:$D$70)) -> -

Sheet 措施优先级准则
A1: DFMEA 和PFMEA 的措施优先级(AP)
A2: 措施优先级是以严重度、频度以及检测评级的综合为基础的，目的是为降低风险而对各项措施进行优先排序
A3: 影响 | B3: S | C3: 对失效起因发生的预测 | D3: O | E3: 探测能力 | F3: D | G3: 措施优先级（AP） | H3: 备注
A4: 对产品或工 厂的影响度 非常高 | B4: 9-10 | C4: 非常高 | D4: 8-10 | E4: 低 - 非常低 | F4: 7-10 | G4: H
E5: 中 | F5: 5-6 | G5: H
E6: 高 | F6: 2-4 | G6: H
E7: 非常高 | F7: 0-1 | G7: H
C8: 高 | D8: 6-7 | E8: 低 - 非常低 | F8: 7-10 | G8: H
E9: 中 | F9: 5-6 | G9: H
E10: 高 | F10: 2-4 | G10: H
E11: 非常高 | F11: 0-1 | G11: H
C12: 中 | D12: 4-5 | E12: 低 - 非常低 | F12: 7-10 | G12: H
E13: 中 | F13: 5-6 | G13: H
E14: 高 | F14: 2-4 | G14: H
E15: 非常高 | F15: 0-1 | G15: M
C16: 低 | D16: 2-3 | E16: 低 - 非常低 | F16: 7-10 | G16: H
E17: 中 | F17: 5-6 | G17: M
E18: 高 | F18: 2-4 | G18: L
E19: 非常高 | F19: 0-1 | G19: L
C20: 非常低 | D20: 0-1 | E20: 非常高 - 非常低 | F20: 1-10 | G20: L
A21: 对产品或工 厂的影响度 高 | B21: 7-8 | C21: 非常高 | D21: 8-10 | E21: 低 - 非常低 | F21: 7-10 | G21: H
E22: 中 | F22: 5-6 | G22: H
E23: 高 | F23: 2-4 | G23: H
E24: 非常高 | F24: 0-1 | G24: H
C25: 高 | D25: 6-7 | E25: 低 - 非常低 | F25: 7-10 | G25: H
E26: 中 | F26: 5-6 | G26: H
E27: 高 | F27: 2-4 | G27: H
E28: 非常高 | F28: 0-1 | G28: M
C29: 中 | D29: 4-5 | E29: 低 - 非常低 | F29: 7-10 | G29: H
E30: 中 | F30: 5-6 | G30: M
E31: 高 | F31: 2-4 | G31: M
E32: 非常高 | F32: 0-1 | G32: M
C33: 低 | D33: 2-3 | E33: 低 - 非常低 | F33: 7-10 | G33: M
E34: 中 | F34: 5-6 | G34: M
E35: 高 | F35: 2-4 | G35: L
E36: 非常高 | F36: 0-1 | G36: L
C37: 非常低 | D37: 0-1 | E37: 非常高 - 非常低 | F37: 1-10 | G37: L
A38: 对产品或工 厂的影响度 中等 | B38: 4-6 | C38: 非常高 | D38: 8-10 | E38: 低 - 非常低 | F38: 7-10 | G38: H
E39: 中 | F39: 5-6 | G39: H
E40: 高 | F40: 2-4 | G40: M
...
